2025-02-18 12:56:53,233 - INFO - [inventory_sync] - Test info message
2025-02-18 12:56:53,233 - WARNING - [inventory_sync] - Test warning message
2025-02-18 12:56:53,234 - ERROR - [inventory_sync] - Test error message
2025-02-18 12:56:53,234 - INFO - [inventory_sync] - Starting sync batch: TEST_BATCH_001
2025-02-18 12:56:53,234 - INFO - [inventory_sync] - Completed sync batch: TEST_BATCH_001
Total records: 1
Successful: 1
Failed: 0
2025-02-18 12:56:53,237 - INFO - [inventory_sync] - Starting sync batch: TEST_BATCH_001
2025-02-18 12:56:55,539 - ERROR - [inventory_sync] - Error sending data to API: Cannot connect to host localhost:3000 ssl:default [The remote computer refused the network connection]
Traceback (most recent call last):
  File "C:\Users\Zerouniquqe\AppData\Roaming\Python\Python313\site-packages\aiohttp\connector.py", line 1115, in _wrap_create_connection
    sock = await aiohappyeyeballs.start_connection(
           ^^^^^^^^^^^^^^^^^^^^^^^^^^^^^^^^^^^^^^^^
    ...<5 lines>...
    )
    ^
  File "C:\Users\Zerouniquqe\AppData\Roaming\Python\Python313\site-packages\aiohappyeyeballs\impl.py", line 98, in start_connection
    raise first_exception
  File "C:\Users\Zerouniquqe\AppData\Roaming\Python\Python313\site-packages\aiohappyeyeballs\_staggered.py", line 127, in run_one_coro
    result = await coro_fn()
             ^^^^^^^^^^^^^^^
  File "C:\Users\Zerouniquqe\AppData\Roaming\Python\Python313\site-packages\aiohappyeyeballs\impl.py", line 163, in _connect_sock
    await loop.sock_connect(sock, address)
  File "C:\Program Files\Python313\Lib\asyncio\proactor_events.py", line 726, in sock_connect
    return await self._proactor.connect(sock, address)
           ^^^^^^^^^^^^^^^^^^^^^^^^^^^^^^^^^^^^^^^^^^^
  File "C:\Program Files\Python313\Lib\asyncio\windows_events.py", line 804, in _poll
    value = callback(transferred, key, ov)
  File "C:\Program Files\Python313\Lib\asyncio\windows_events.py", line 600, in finish_connect
    ov.getresult()
    ~~~~~~~~~~~~^^
ConnectionRefusedError: [WinError 1225] The remote computer refused the network connection

The above exception was the direct cause of the following exception:

Traceback (most recent call last):
  File "C:\Users\Zerouniquqe\Documents\projects\label_printer\src\inventory_sync\sync_manager.py", line 30, in _send_to_api
    async with session.post(url, json=data) as response:
               ~~~~~~~~~~~~^^^^^^^^^^^^^^^^
  File "C:\Users\Zerouniquqe\AppData\Roaming\Python\Python313\site-packages\aiohttp\client.py", line 1425, in __aenter__
    self._resp: _RetType = await self._coro
                           ^^^^^^^^^^^^^^^^
  File "C:\Users\Zerouniquqe\AppData\Roaming\Python\Python313\site-packages\aiohttp\client.py", line 703, in _request
    conn = await self._connector.connect(
           ^^^^^^^^^^^^^^^^^^^^^^^^^^^^^^
        req, traces=traces, timeout=real_timeout
        ^^^^^^^^^^^^^^^^^^^^^^^^^^^^^^^^^^^^^^^^
    )
    ^
  File "C:\Users\Zerouniquqe\AppData\Roaming\Python\Python313\site-packages\aiohttp\connector.py", line 548, in connect
    proto = await self._create_connection(req, traces, timeout)
            ^^^^^^^^^^^^^^^^^^^^^^^^^^^^^^^^^^^^^^^^^^^^^^^^^^^
  File "C:\Users\Zerouniquqe\AppData\Roaming\Python\Python313\site-packages\aiohttp\connector.py", line 1056, in _create_connection
    _, proto = await self._create_direct_connection(req, traces, timeout)
               ^^^^^^^^^^^^^^^^^^^^^^^^^^^^^^^^^^^^^^^^^^^^^^^^^^^^^^^^^^
  File "C:\Users\Zerouniquqe\AppData\Roaming\Python\Python313\site-packages\aiohttp\connector.py", line 1400, in _create_direct_connection
    raise last_exc
  File "C:\Users\Zerouniquqe\AppData\Roaming\Python\Python313\site-packages\aiohttp\connector.py", line 1369, in _create_direct_connection
    transp, proto = await self._wrap_create_connection(
                    ^^^^^^^^^^^^^^^^^^^^^^^^^^^^^^^^^^^
    ...<7 lines>...
    )
    ^
  File "C:\Users\Zerouniquqe\AppData\Roaming\Python\Python313\site-packages\aiohttp\connector.py", line 1130, in _wrap_create_connection
    raise client_error(req.connection_key, exc) from exc
aiohttp.client_exceptions.ClientConnectorError: Cannot connect to host localhost:3000 ssl:default [The remote computer refused the network connection]
2025-02-18 12:58:20,718 - INFO - [inventory_sync] - Test info message
2025-02-18 12:58:20,719 - WARNING - [inventory_sync] - Test warning message
2025-02-18 12:58:20,719 - ERROR - [inventory_sync] - Test error message
2025-02-18 12:58:20,719 - INFO - [inventory_sync] - Starting sync batch: TEST_BATCH_001
2025-02-18 12:58:20,720 - INFO - [inventory_sync] - Completed sync batch: TEST_BATCH_001
Total records: 1
Successful: 1
Failed: 0
2025-02-18 12:58:20,724 - INFO - [inventory_sync] - Starting sync batch: TEST_BATCH_001
2025-02-18 12:58:41,765 - ERROR - [inventory_sync] - Error sending data to API: Cannot connect to host 192.168.0.10:3000 ssl:default [The semaphore timeout period has expired]
Traceback (most recent call last):
  File "C:\Users\Zerouniquqe\AppData\Roaming\Python\Python313\site-packages\aiohttp\connector.py", line 1115, in _wrap_create_connection
    sock = await aiohappyeyeballs.start_connection(
           ^^^^^^^^^^^^^^^^^^^^^^^^^^^^^^^^^^^^^^^^
    ...<5 lines>...
    )
    ^
  File "C:\Users\Zerouniquqe\AppData\Roaming\Python\Python313\site-packages\aiohappyeyeballs\impl.py", line 93, in start_connection
    raise first_exception
  File "C:\Users\Zerouniquqe\AppData\Roaming\Python\Python313\site-packages\aiohappyeyeballs\impl.py", line 71, in start_connection
    sock = await _connect_sock(
           ^^^^^^^^^^^^^^^^^^^^
        current_loop, exceptions, addrinfo, local_addr_infos
        ^^^^^^^^^^^^^^^^^^^^^^^^^^^^^^^^^^^^^^^^^^^^^^^^^^^^
    )
    ^
  File "C:\Users\Zerouniquqe\AppData\Roaming\Python\Python313\site-packages\aiohappyeyeballs\impl.py", line 163, in _connect_sock
    await loop.sock_connect(sock, address)
  File "C:\Program Files\Python313\Lib\asyncio\proactor_events.py", line 726, in sock_connect
    return await self._proactor.connect(sock, address)
           ^^^^^^^^^^^^^^^^^^^^^^^^^^^^^^^^^^^^^^^^^^^
  File "C:\Program Files\Python313\Lib\asyncio\windows_events.py", line 804, in _poll
    value = callback(transferred, key, ov)
  File "C:\Program Files\Python313\Lib\asyncio\windows_events.py", line 600, in finish_connect
    ov.getresult()
    ~~~~~~~~~~~~^^
OSError: [WinError 121] The semaphore timeout period has expired

The above exception was the direct cause of the following exception:

Traceback (most recent call last):
  File "C:\Users\Zerouniquqe\Documents\projects\label_printer\src\inventory_sync\sync_manager.py", line 30, in _send_to_api
    async with session.post(url, json=data) as response:
               ~~~~~~~~~~~~^^^^^^^^^^^^^^^^
  File "C:\Users\Zerouniquqe\AppData\Roaming\Python\Python313\site-packages\aiohttp\client.py", line 1425, in __aenter__
    self._resp: _RetType = await self._coro
                           ^^^^^^^^^^^^^^^^
  File "C:\Users\Zerouniquqe\AppData\Roaming\Python\Python313\site-packages\aiohttp\client.py", line 703, in _request
    conn = await self._connector.connect(
           ^^^^^^^^^^^^^^^^^^^^^^^^^^^^^^
        req, traces=traces, timeout=real_timeout
        ^^^^^^^^^^^^^^^^^^^^^^^^^^^^^^^^^^^^^^^^
    )
    ^
  File "C:\Users\Zerouniquqe\AppData\Roaming\Python\Python313\site-packages\aiohttp\connector.py", line 548, in connect
    proto = await self._create_connection(req, traces, timeout)
            ^^^^^^^^^^^^^^^^^^^^^^^^^^^^^^^^^^^^^^^^^^^^^^^^^^^
  File "C:\Users\Zerouniquqe\AppData\Roaming\Python\Python313\site-packages\aiohttp\connector.py", line 1056, in _create_connection
    _, proto = await self._create_direct_connection(req, traces, timeout)
               ^^^^^^^^^^^^^^^^^^^^^^^^^^^^^^^^^^^^^^^^^^^^^^^^^^^^^^^^^^
  File "C:\Users\Zerouniquqe\AppData\Roaming\Python\Python313\site-packages\aiohttp\connector.py", line 1400, in _create_direct_connection
    raise last_exc
  File "C:\Users\Zerouniquqe\AppData\Roaming\Python\Python313\site-packages\aiohttp\connector.py", line 1369, in _create_direct_connection
    transp, proto = await self._wrap_create_connection(
                    ^^^^^^^^^^^^^^^^^^^^^^^^^^^^^^^^^^^
    ...<7 lines>...
    )
    ^
  File "C:\Users\Zerouniquqe\AppData\Roaming\Python\Python313\site-packages\aiohttp\connector.py", line 1130, in _wrap_create_connection
    raise client_error(req.connection_key, exc) from exc
aiohttp.client_exceptions.ClientConnectorError: Cannot connect to host 192.168.0.10:3000 ssl:default [The semaphore timeout period has expired]
2025-02-18 13:00:44,469 - INFO - [inventory_sync] - Test info message
2025-02-18 13:00:44,470 - WARNING - [inventory_sync] - Test warning message
2025-02-18 13:00:44,470 - ERROR - [inventory_sync] - Test error message
2025-02-18 13:00:44,470 - INFO - [inventory_sync] - Starting sync batch: TEST_BATCH_001
2025-02-18 13:00:44,470 - INFO - [inventory_sync] - Completed sync batch: TEST_BATCH_001
Total records: 1
Successful: 1
Failed: 0
2025-02-18 13:00:44,477 - INFO - [inventory_sync] - Starting sync batch: TEST_BATCH_001
2025-02-18 13:00:44,980 - ERROR - [inventory_sync] - Error sending data to API: Cannot connect to host httpbin.org:443 ssl:True [SSLCertVerificationError: (1, '[SSL: CERTIFICATE_VERIFY_FAILED] certificate verify failed: Basic Constraints of CA cert not marked critical (_ssl.c:1020)')]
Traceback (most recent call last):
  File "C:\Users\Zerouniquqe\AppData\Roaming\Python\Python313\site-packages\aiohttp\connector.py", line 1122, in _wrap_create_connection
    return await self._loop.create_connection(*args, **kwargs, sock=sock)
           ^^^^^^^^^^^^^^^^^^^^^^^^^^^^^^^^^^^^^^^^^^^^^^^^^^^^^^^^^^^^^^
  File "C:\Program Files\Python313\Lib\asyncio\base_events.py", line 1182, in create_connection
    transport, protocol = await self._create_connection_transport(
                          ^^^^^^^^^^^^^^^^^^^^^^^^^^^^^^^^^^^^^^^^
    ...<2 lines>...
        ssl_shutdown_timeout=ssl_shutdown_timeout)
        ^^^^^^^^^^^^^^^^^^^^^^^^^^^^^^^^^^^^^^^^^^
  File "C:\Program Files\Python313\Lib\asyncio\base_events.py", line 1215, in _create_connection_transport
    await waiter
  File "C:\Program Files\Python313\Lib\asyncio\sslproto.py", line 578, in _on_handshake_complete
    raise handshake_exc
  File "C:\Program Files\Python313\Lib\asyncio\sslproto.py", line 560, in _do_handshake
    self._sslobj.do_handshake()
    ~~~~~~~~~~~~~~~~~~~~~~~~~^^
  File "C:\Program Files\Python313\Lib\ssl.py", line 951, in do_handshake
    self._sslobj.do_handshake()
    ~~~~~~~~~~~~~~~~~~~~~~~~~^^
ssl.SSLCertVerificationError: [SSL: CERTIFICATE_VERIFY_FAILED] certificate verify failed: Basic Constraints of CA cert not marked critical (_ssl.c:1020)

The above exception was the direct cause of the following exception:

Traceback (most recent call last):
  File "C:\Users\Zerouniquqe\Documents\projects\label_printer\src\inventory_sync\sync_manager.py", line 34, in _send_to_api
    async with session.post(url, json=data) as response:
               ~~~~~~~~~~~~^^^^^^^^^^^^^^^^
  File "C:\Users\Zerouniquqe\AppData\Roaming\Python\Python313\site-packages\aiohttp\client.py", line 1425, in __aenter__
    self._resp: _RetType = await self._coro
                           ^^^^^^^^^^^^^^^^
  File "C:\Users\Zerouniquqe\AppData\Roaming\Python\Python313\site-packages\aiohttp\client.py", line 703, in _request
    conn = await self._connector.connect(
           ^^^^^^^^^^^^^^^^^^^^^^^^^^^^^^
        req, traces=traces, timeout=real_timeout
        ^^^^^^^^^^^^^^^^^^^^^^^^^^^^^^^^^^^^^^^^
    )
    ^
  File "C:\Users\Zerouniquqe\AppData\Roaming\Python\Python313\site-packages\aiohttp\connector.py", line 548, in connect
    proto = await self._create_connection(req, traces, timeout)
            ^^^^^^^^^^^^^^^^^^^^^^^^^^^^^^^^^^^^^^^^^^^^^^^^^^^
  File "C:\Users\Zerouniquqe\AppData\Roaming\Python\Python313\site-packages\aiohttp\connector.py", line 1056, in _create_connection
    _, proto = await self._create_direct_connection(req, traces, timeout)
               ^^^^^^^^^^^^^^^^^^^^^^^^^^^^^^^^^^^^^^^^^^^^^^^^^^^^^^^^^^
  File "C:\Users\Zerouniquqe\AppData\Roaming\Python\Python313\site-packages\aiohttp\connector.py", line 1400, in _create_direct_connection
    raise last_exc
  File "C:\Users\Zerouniquqe\AppData\Roaming\Python\Python313\site-packages\aiohttp\connector.py", line 1369, in _create_direct_connection
    transp, proto = await self._wrap_create_connection(
                    ^^^^^^^^^^^^^^^^^^^^^^^^^^^^^^^^^^^
    ...<7 lines>...
    )
    ^
  File "C:\Users\Zerouniquqe\AppData\Roaming\Python\Python313\site-packages\aiohttp\connector.py", line 1124, in _wrap_create_connection
    raise ClientConnectorCertificateError(req.connection_key, exc) from exc
aiohttp.client_exceptions.ClientConnectorCertificateError: Cannot connect to host httpbin.org:443 ssl:True [SSLCertVerificationError: (1, '[SSL: CERTIFICATE_VERIFY_FAILED] certificate verify failed: Basic Constraints of CA cert not marked critical (_ssl.c:1020)')]
2025-02-18 13:01:17,869 - INFO - [inventory_sync] - Test info message
2025-02-18 13:01:17,870 - WARNING - [inventory_sync] - Test warning message
2025-02-18 13:01:17,870 - ERROR - [inventory_sync] - Test error message
2025-02-18 13:01:17,871 - INFO - [inventory_sync] - Starting sync batch: TEST_BATCH_001
2025-02-18 13:01:17,871 - INFO - [inventory_sync] - Completed sync batch: TEST_BATCH_001
Total records: 1
Successful: 1
Failed: 0
2025-02-18 13:01:17,876 - INFO - [inventory_sync] - Starting sync batch: TEST_BATCH_001
2025-02-18 13:01:19,073 - INFO - [inventory_sync] - API success for batch TEST_BATCH_001: {'args': {}, 'data': '{"source": "test", "timestamp": "2025-02-18T18:01:17.876128Z", "batch_id": "TEST_BATCH_001", "items": [{"serialnumber": "TEST123456", "manufacturer": "Dell", "model": "Latitude 5420"}], "metadata": {"total_items": 1, "version": "1.0", "checksum": "test_checksum"}}', 'files': {}, 'form': {}, 'headers': {'Accept': '*/*', 'Accept-Encoding': 'gzip, deflate', 'Content-Length': '264', 'Content-Type': 'application/json', 'Host': 'httpbin.org', 'User-Agent': 'Python/3.13 aiohttp/3.11.12', 'X-Amzn-Trace-Id': 'Root=1-67b4caed-67ad96071b74c0711bb50a3a'}, 'json': {'batch_id': 'TEST_BATCH_001', 'items': [{'manufacturer': 'Dell', 'model': 'Latitude 5420', 'serialnumber': 'TEST123456'}], 'metadata': {'checksum': 'test_checksum', 'total_items': 1, 'version': '1.0'}, 'source': 'test', 'timestamp': '2025-02-18T18:01:17.876128Z'}, 'origin': '99.210.244.207', 'url': 'https://httpbin.org/post'}
2025-02-18 13:01:19,075 - INFO - [inventory_sync] - Completed sync batch: TEST_BATCH_001
Total records: 1
Successful: 1
Failed: 0
2025-02-18 13:03:08,336 - INFO - [inventory_sync] - Test info message
2025-02-18 13:03:08,337 - WARNING - [inventory_sync] - Test warning message
2025-02-18 13:03:08,337 - ERROR - [inventory_sync] - Test error message
2025-02-18 13:03:08,337 - INFO - [inventory_sync] - Starting sync batch: TEST_BATCH_001
2025-02-18 13:03:08,338 - INFO - [inventory_sync] - Completed sync batch: TEST_BATCH_001
Total records: 1
Successful: 1
Failed: 0
2025-02-18 13:03:08,341 - INFO - [inventory_sync] - Starting sync batch: TEST_BATCH_20250218_130308
2025-02-18 13:03:08,861 - ERROR - [inventory_sync] - API error for batch TEST_BATCH_20250218_130308: Status 401, Response: {'success': False, 'error': 'No token provided', 'code': 'AuthenticationError'}
2025-02-18 13:03:08,862 - INFO - [inventory_sync] - Completed sync batch: TEST_BATCH_20250218_130308
Total records: 1
Successful: 0
Failed: 1
2025-02-18 13:03:47,312 - INFO - [inventory_sync] - Test info message
2025-02-18 13:03:47,312 - WARNING - [inventory_sync] - Test warning message
2025-02-18 13:03:47,312 - ERROR - [inventory_sync] - Test error message
2025-02-18 13:03:47,313 - INFO - [inventory_sync] - Starting sync batch: TEST_BATCH_001
2025-02-18 13:03:47,313 - INFO - [inventory_sync] - Completed sync batch: TEST_BATCH_001
Total records: 1
Successful: 1
Failed: 0
2025-02-18 13:03:47,318 - INFO - [inventory_sync] - Starting sync batch: TEST_BATCH_20250218_130347
2025-02-18 13:03:47,584 - ERROR - [inventory_sync] - API error for batch TEST_BATCH_20250218_130347: Status 401, Response: {'success': False, 'error': 'Invalid token', 'code': 'AuthenticationError'}
2025-02-18 13:03:47,585 - INFO - [inventory_sync] - Completed sync batch: TEST_BATCH_20250218_130347
Total records: 1
Successful: 0
Failed: 1
2025-02-18 13:09:02,067 - INFO - [inventory_sync] - Test info message
2025-02-18 13:09:02,067 - WARNING - [inventory_sync] - Test warning message
2025-02-18 13:09:02,068 - ERROR - [inventory_sync] - Test error message
2025-02-18 13:09:02,068 - INFO - [inventory_sync] - Starting sync batch: TEST_BATCH_001
2025-02-18 13:09:02,068 - INFO - [inventory_sync] - Completed sync batch: TEST_BATCH_001
Total records: 1
Successful: 1
Failed: 0
2025-02-18 13:09:02,405 - INFO - [inventory_sync] - Successfully logged in and got token
2025-02-18 13:09:02,409 - INFO - [inventory_sync] - Starting sync batch: TEST_BATCH_20250218_130902
2025-02-18 13:09:02,666 - ERROR - [inventory_sync] - API error for batch TEST_BATCH_20250218_130902: Status 400, Response: {'success': False, 'error': 'Invalid checksum'}
2025-02-18 13:09:02,667 - INFO - [inventory_sync] - Completed sync batch: TEST_BATCH_20250218_130902
Total records: 1
Successful: 0
Failed: 1
2025-02-18 13:14:07,972 - INFO - [inventory_sync] - Test info message
2025-02-18 13:14:07,973 - WARNING - [inventory_sync] - Test warning message
2025-02-18 13:14:07,973 - ERROR - [inventory_sync] - Test error message
2025-02-18 13:14:07,973 - INFO - [inventory_sync] - Starting sync batch: TEST_BATCH_001
2025-02-18 13:14:07,974 - INFO - [inventory_sync] - Completed sync batch: TEST_BATCH_001
Total records: 1
Successful: 1
Failed: 0
2025-02-18 13:14:08,342 - INFO - [inventory_sync] - Successfully logged in and got token
2025-02-18 13:14:08,344 - INFO - [inventory_sync] - Starting sync batch: TEST_BATCH_20250218_131408
2025-02-18 13:14:08,555 - ERROR - [inventory_sync] - API error for batch TEST_BATCH_20250218_131408: Status 400, Response: {'success': False, 'error': 'Invalid checksum'}
2025-02-18 13:14:08,556 - INFO - [inventory_sync] - Completed sync batch: TEST_BATCH_20250218_131408
Total records: 1
Successful: 0
Failed: 1
